<?xml version="1.0" encoding="utf-8"?>
<!-- This URDF was automatically created by SolidWorks to URDF Exporter! Originally created by Stephen Brawner (brawner@gmail.com) 
     Commit Version: 1.6.0-4-g7f85cfe  Build Version: 1.6.7995.38578
     For more information, please see http://wiki.ros.org/sw_urdf_exporter -->
<robot
  name="XIAOCHE2">
  <link
    name="base_link">
    <inertial>
      <origin
        xyz="2.77555756156289E-17 1.11022302462516E-16 -0.025029363393499"
        rpy="0 0 0" />
      <mass
        value="1.3313153226149" />
      <inertia
        ixx="0.0026238376441774"
        ixy="2.28392604790396E-19"
        ixz="7.31836466427715E-19"
        iyy="0.00404589965886898"
        iyz="4.81596900698379E-20"
        izz="0.00611723172124818" />
    </inertial>
    <visual>
      <origin
        xyz="0 0 0"
        rpy="0 0 0" />
      <geometry>
        <mesh
          filename="package://XIAOCHE2/meshes/base_link.STL" />
      </geometry>
      <material
        name="">
        <color
          rgba="1 1 1 1" />
      </material>
    </visual>
    <collision>
      <origin
        xyz="0 0 0"
        rpy="0 0 0" />
      <geometry>
        <mesh
          filename="package://XIAOCHE2/meshes/base_link.STL" />
      </geometry>
    </collision>
  </link>
  <link
    name="wheel_L1">
    <inertial>
      <origin
        xyz="-1.0588E-07 -0.0066281 2.194E-08"
        rpy="0 0 0" />
      <mass
        value="0.14742" />
      <inertia
        ixx="6.8277E-05"
        ixy="6.2462E-11"
        ixz="1.4769E-10"
        iyy="0.00010916"
        iyz="5.8683E-11"
        izz="6.8277E-05" />
    </inertial>
    <visual>
      <origin
        xyz="0 0 0"
        rpy="0 0 0" />
      <geometry>
        <mesh
          filename="package://XIAOCHE2/meshes/wheel_L1.STL" />
      </geometry>
      <material
        name="">
        <color
          rgba="1 1 1 1" />
      </material>
    </visual>
    <collision>
      <origin
        xyz="0 0 0"
        rpy="0 0 0" />
      <geometry>
        <mesh
          filename="package://XIAOCHE2/meshes/wheel_L1.STL" />
      </geometry>
    </collision>
  </link>
  <joint
    name="wheel_L1J"
    type="continuous">
    <origin
      xyz="0.07 0.11556 -0.031"
      rpy="0 0 0" />
    <parent
      link="base_link" />
    <child
      link="wheel_L1" />
    <axis
      xyz="0 1 0" />
  </joint>
  <link
    name="wheel_L2">
    <inertial>
      <origin
        xyz="-1.0614E-07 -0.0066281 2.2975E-08"
        rpy="0 0 0" />
      <mass
        value="0.14742" />
      <inertia
        ixx="6.8277E-05"
        ixy="6.4334E-11"
        ixz="1.4887E-10"
        iyy="0.00010916"
        iyz="5.5855E-11"
        izz="6.8277E-05" />
    </inertial>
    <visual>
      <origin
        xyz="0 0 0"
        rpy="0 0 0" />
      <geometry>
        <mesh
          filename="package://XIAOCHE2/meshes/wheel_L2.STL" />
      </geometry>
      <material
        name="">
        <color
          rgba="1 1 1 1" />
      </material>
    </visual>
    <collision>
      <origin
        xyz="0 0 0"
        rpy="0 0 0" />
      <geometry>
        <mesh
          filename="package://XIAOCHE2/meshes/wheel_L2.STL" />
      </geometry>
    </collision>
  </link>
  <joint
    name="wheel_L2J"
    type="continuous">
    <origin
      xyz="-0.07 0.11556 -0.031"
      rpy="0 0 0" />
    <parent
      link="base_link" />
    <child
      link="wheel_L2" />
    <axis
      xyz="0 1 0" />
  </joint>
  <link
    name="wheel_R1">
    <inertial>
      <origin
        xyz="-1.28159414330975E-08 0.00662808543279114 -6.2952978274744E-08"
        rpy="0 0 0" />
      <mass
        value="0.147415081884935" />
      <inertia
        ixx="6.827662650286E-05"
        ixy="-6.32090085922517E-11"
        ixz="1.46603007123518E-10"
        iyy="0.000109158838418431"
        iyz="-1.71182807994737E-11"
        izz="6.82765358575209E-05" />
    </inertial>
    <visual>
      <origin
        xyz="0 0 0"
        rpy="0 0 0" />
      <geometry>
        <mesh
          filename="package://XIAOCHE2/meshes/wheel_R1.STL" />
      </geometry>
      <material
        name="">
        <color
          rgba="1 1 1 1" />
      </material>
    </visual>
    <collision>
      <origin
        xyz="0 0 0"
        rpy="0 0 0" />
      <geometry>
        <mesh
          filename="package://XIAOCHE2/meshes/wheel_R1.STL" />
      </geometry>
    </collision>
  </link>
  <joint
    name="wheel_R1J"
    type="continuous">
    <origin
      xyz="0.07 -0.11556 -0.031"
      rpy="0 0 0" />
    <parent
      link="base_link" />
    <child
      link="wheel_R1" />
    <axis
      xyz="0 -1 0" />
  </joint>
  <link
    name="wheel_R2">
    <inertial>
      <origin
        xyz="-1.34423054909405E-08 0.00662808630362 -6.12543565869927E-08"
        rpy="0 0 0" />
      <mass
        value="0.147415107639338" />
      <inertia
        ixx="6.82766415189075E-05"
        ixy="-6.76853638150117E-11"
        ixz="1.44585220950724E-10"
        iyy="0.000109158853195658"
        iyz="-1.46615940712995E-11"
        izz="6.82765449651514E-05" />
    </inertial>
    <visual>
      <origin
        xyz="0 0 0"
        rpy="0 0 0" />
      <geometry>
        <mesh
          filename="package://XIAOCHE2/meshes/wheel_R2.STL" />
      </geometry>
      <material
        name="">
        <color
          rgba="1 1 1 1" />
      </material>
    </visual>
    <collision>
      <origin
        xyz="0 0 0"
        rpy="0 0 0" />
      <geometry>
        <mesh
          filename="package://XIAOCHE2/meshes/wheel_R2.STL" />
      </geometry>
    </collision>
  </link>
  <joint
    name="wheel_R12J"
    type="continuous">
    <origin
      xyz="-0.07 -0.11556 -0.031"
      rpy="0 0 0" />
    <parent
      link="base_link" />
    <child
      link="wheel_R2" />
    <axis
      xyz="0 -1 0" />
  </joint>
</robot>